Workbook

Sheet Start here
A1: Mada Trips · Social Media Plan · November 2026
A2: Instagram · TikTok · X · LinkedIn. Researched 18 Oct 2026. Times are Riyadh (AST, UTC+3).
A4: Situation | B4: Mada is a new account on every platform. Month one sets up the profiles, the recurring series that make us recognisable, and the habit of posting daily.
B5: Riyadh's airport (RUH) was hit by Houthi missiles and drones several times in early-mid October 2026 and reopened on 18 Oct. Several foreign airlines are still suspended into November (Lufthansa to 18 Nov, KLM to 31 Oct, BA limited from 3 Nov). The plan leads with domestic and short-haul trips, Riyadh Season, practical help and calm reassurance. There are no airport jokes and no 'fly now' hype. See the sensitivity protocol.
B6: Several big December events were cancelled or moved this season (Red Sea Film Festival postponed to 2027, MDLBEAST Soundstorm 2026 cancelled, Formula E moved from Diriyah to Jeddah, Six Kings Slam moved to 27-30 Dec). Re-check every event date the week it is posted.
B7: The calendar's biggest commercial moments are the school autumn break (20-28 Nov), White Friday (27 Nov), and Rajab (from ~10 Dec), which opens Umrah planning for Ramadan 1448 (~8 Feb 2027).
A9: Objectives | B9: Be found: Rank in TikTok and Instagram search for high-intent Arabic travel and visa terms (تأشيرة شنغن, إجازة الخريف, العلا, باقات عمرة).
B10: Be remembered: Make 4-5 named series that people recognise and follow: One Call, Visa in 60, Weekend Radar, Concierge Confessions, Behind the Curtain.
B11: Be trusted: Show the people behind the service. No Saudi OTA puts a real advisor on camera, and that is our white space.
B12: Convert: Move intent to WhatsApp: every post has one CTA, and every DM gets an answer within the hour during working hours.
A14: How to use this file | B14: Calendar: every post with its hook, poster text (EN/AR), caption (AR/EN), keywords, hashtags, CTA and production direction. Filter by platform, week or pillar.
B15: Fill in Owner and Status for each post. The Status dropdown runs Idea → Scripted → Shot → Designed → Approved → Scheduled → Posted (or Paused).
B16: After posting, fill the yellow results columns (Reach … Saves). The engagement rate calculates itself, and 'KPIs & tracking' rolls it up by platform.
B17: Rows flagged in the Notes column (OFFER, APPROVAL, SENSITIVITY) can't be scheduled without that sign-off.
B18: Month view: the whole month at a glance. Guidelines, Keywords, Competitors and Moments hold the research behind every post.
A20: Posts this month
A21: Platform | B21: Posts (counted from Calendar)
A22: Instagram | B22: =COUNTIF(Calendar!$E:$E,"Instagram") -> 35
A23: TikTok | B23: =COUNTIF(Calendar!$E:$E,"TikTok") -> 34
A24: X | B24: =COUNTIF(Calendar!$E:$E,"X") -> 30
A25: LinkedIn | B25: =COUNTIF(Calendar!$E:$E,"LinkedIn") -> 12
A26: Total | B26: =SUM(B22:B25) -> 111

Sheet Calendar
A1: # | B1: Date | C1: Day | D1: Time (AST) | E1: Platform | F1: Format | G1: Pillar | H1: Series | I1: Moment / trend | J1: Working title | K1: Hook (first 1-3s / first line) | L1: On-poster / on-screen text (EN) | M1: On-poster / on-screen text (AR) | N1: Caption / copy (AR) | O1: Caption / copy (EN) | P1: Search keywords | Q1: Hashtags (max 5) | R1: CTA | S1: Visual / audio / production direction | T1: Notes · approvals · risks | U1: Owner | V1: Status | W1: Reach | X1: Views | Y1: Likes | Z1: Comments | AA1: Shares | AB1: Saves | AC1: Eng. rate
A2: 1 | B2: 46327 | C2: Sun | D2: 20:30 | E2: Instagram | F2: Reel 30s | G2: Moments & Offers | I2: Brand launch | J2: Launch film: Every horizon, within reach | K2: Black screen, one word in gold: مدى / Reach | L2: Every horizon, within reach. | M2: كل أفق، في متناولك. | N2: مادا يعني المدى. ومن اليوم، رحلتك وفعاليتك وفريقك… كلها بمكالمة وحدة. تذاكر، فنادق، تأشيرات، فعاليات، كوادر وتقنية — من الرياض لكل أفق. تابعنا، القادم أجمل 🌙 | O2: Mada is Arabic for reach. Flights, stays, visas, events, crews and tech. From Riyadh to every horizon. One call. Everything moves. | P2: وكالة سفر الرياض, Riyadh travel agency, مادا للسفر | Q2: #مادا #MadaTrips #الرياض #سفر #RiyadhTravel | R2: Follow + tap the WhatsApp button in bio | S2: Cinematic 6-scene cut, 4-5s each: dunes at sunrise → boarding gate → hotel door opening to a ready room → stage lights warming up → concierge answering a phone at 03:00 → logo resolve. Calm Najdi VO (male or female). Warm sand/green grade. Ambient oud with a slow rise. Burned-in Arabic subtitles + English. | T2: PIN to profile. Shoot original footage only (Instagram stops recommending reposted clips since Apr 2026). | V2: Scripted | AC2: =IF(OR(W2="",W2=0),"",(Y2+Z2+AA2+AB2)/W2)
A3: 2 | B3: 46327 | C3: Sun | D3: 21:00 | E3: TikTok | F3: Video 20s | G3: One Call | I3: Brand launch | J3: POV: you said it once and it just happened | K3: On-screen: لما تقول طلبك مرة وحدة… 👀 | L3: You said it once. We did the rest. | M3: قلتها مرة… والباقي علينا | N3: أول فيديو لنا 👋 احنا مادا من الرياض. قل طلبك مرة، والباقي علينا ✈️🏨 وش أول وجهة نخطط لها لك؟ اكتبها بالتعليقات 👇 | O3: Our first video. We're Mada from Riyadh. Say it once and we handle the rest. Where should we plan first? Comment below. | P3: تخطيط رحلة, رحلة العلا, travel planner Riyadh | Q3: #مادا #سفر #العلا #السعودية #tiktoksaudi | R3: Comment your dream destination | S3: Open on a real-sounding voice note bubble: 'أبي آخذ أهلي العلا الويكند الجاي'. Jump cuts in sync with a trending beat: laptop, WhatsApp confirmations popping (flight ✓ hotel ✓ transfer ✓), then the family (from behind) walking into Hegra at golden hour. 9:16, captions on. | T3: Reply to every comment with a video reply over the following days. That reply series feeds week 2. | V3: Scripted | AC3: =IF(OR(W3="",W3=0),"",(Y3+Z3+AA3+AB3)/W3)
A4: 3 | B4: 46327 | C4: Sun | D4: 13:00 | E4: X | F4: Post (pinned) | G4: Moments & Offers | I4: Brand launch | J4: Launch post | K4: مادا يعني المدى. | N4: مادا يعني المدى. من اليوم، كل أفق في متناولك: سفر، تذاكر، فنادق، تأشيرات، فعاليات، كوادر وتقنية. فريق واحد يرد عليك حتى الساعة ٣ الفجر. وش الوجهة اللي تحلم فيها هالشتاء؟ 👇 | O4: Mada means reach. From today every horizon is within reach: travel, tickets, hotels, visas, events, crews and tech. One team that picks up even at 3 a.m. Where are you dreaming of this winter? | P4: وكالة سفر, سفر الشتاء | Q4: #مادا | R4: Reply with a destination | S4: Attach the launch film's 15s cut (native upload, not a link). | T4: Pin. Reply to every answer within the hour, since replies feed ranking. | V4: Scripted | AC4: =IF(OR(W4="",W4=0),"",(Y4+Z4+AA4+AB4)/W4)
A5: 4 | B5: 46327 | C5: Sun | D5: 09:30 | E5: LinkedIn | F5: Image + post | G5: Events & Business | I5: Brand launch | J5: Mada Trips opens its doors | K5: One partner for everything that moves. | L5: One partner for everything that moves. | M5: شريك واحد لكل ما يتحرك | O5: Today Mada Trips opens its doors in Riyadh. Most organisations juggle seven vendors to move one delegation: an airline desk, a hotel contact, a visa agent, an event producer, a crew supplier, an IT vendor and someone who chases them all. We built Mada so that is one call. → Travel, ticketing and hotels → Visa support and business services → Manpower and specialist supply → Events and the IT beneath them One team, one point of contact, one report that accounts for every riyal. If you are planning a delegation, a conference or a project mobilisation for 2027, we'd like to hear about it. | P5: corporate travel Saudi Arabia, event management Riyadh, manpower supply KSA | Q5: #Riyadh #CorporateTravel #EventManagement #Vision2030 | R5: Message us / visit the website | S5: Single 1200x1500 image: sand background, green headline, the 9 service names in a quiet grid, symbol in gold. Founder reshares with a personal line within 2 hours. | T5: Ask the founder and every team member to comment with substance (not 'congrats') in the first hour. | V5: Scripted | AC5: =IF(OR(W5="",W5=0),"",(Y5+Z5+AA5+AB5)/W5)
A6: 5 | B6: 46328 | C6: Mon | D6: 20:30 | E6: Instagram | F6: Carousel 10 | G6: One Call | I6: Launch week | J6: 9 services. 1 call. | K6: Slide 1: Say it once. We'll take it from there. | L6: Say it once. We'll take it from there. | M6: قلها مرة… ونكمّل عنك | N6: تسع خدمات، ورقم واحد. ١ السفر ٢ التذاكر ٣ الفنادق ٤ التأشيرات ٥ خدمات الأعمال ٦ الكوادر ٧ المختصين ٨ الفعاليات ٩ الحلول التقنية احفظ المنشور لين تحتاجنا 📌 | O6: Nine services, one number. Travel, ticketing, hotels, visas, business services, manpower, specialists, events, IT. Save this for when you need us. | P6: خدمات سفر, حجز فنادق, تأشيرات, تنظيم فعاليات | Q6: #مادا #MadaTrips #خدمات_سفر #تنظيم_فعاليات #الرياض | R6: Save + share with the person who always plans | S6: 4:5 (1080x1350). One service per slide: a single real photo, a 3-word promise, the Arabic word large in Reem Kufi. Slide 10: WhatsApp number + 'One call. Everything moves.' Keep text off the bottom 300px. | V6: Scripted | AC6: =IF(OR(W6="",W6=0),"",(Y6+Z6+AA6+AB6)/W6)
A7: 6 | B7: 46328 | C7: Mon | D7: 21:00 | E7: TikTok | F7: Video 50s | G7: Know Before You Go | H7: Visa in 60 | I7: Evergreen visa (rule since Apr 2024) | J7: Schengen 5-year visa for Saudis | K7: Spoken + on-screen in the first 2s: فيزا شنغن ٥ سنوات؟ حتى من أول مرة! | L7: 5-year Schengen. Even on your first application. | M7: شنغن ٥ سنوات… حتى من أول مرة | N7: فيزا شنغن متعددة لين ٥ سنوات للسعوديين المقيمين في المملكة — حتى لو أول مرة تقدم ✅ بس فيه ٣ أشياء لازم تعرفها قبل الموعد 👇 احفظ الفيديو وأرسله لرفيق السفر. | O7: Saudi nationals living in the Kingdom can get a multiple-entry Schengen visa of up to 5 years, even on a first application. Here are 3 things to know before your appointment. | P7: تأشيرة شنغن, فيزا شنغن للسعوديين, شنغن ٥ سنوات, Schengen visa Saudi | Q7: #تأشيرة_شنغن #فيزا #سفر #السعودية #مادا | R7: Save + 'send to your travel buddy' | S7: Concierge on camera, green-screen behind with the EU visa page. 3 numbered points as text pops: (1) validity is at the embassy's discretion, (2) apply 3-6 weeks before travel, (3) bring bank statement + employment letter + insurance. End card: 'Want us to prepare your file? Link in bio'. | T7: Legal check: say 'up to' and 'at the embassy's discretion'. Never promise approval. | V7: Scripted | AC7: =IF(OR(W7="",W7=0),"",(Y7+Z7+AA7+AB7)/W7)
A8: 7 | B8: 46328 | C8: Mon | D8: 12:30 | E8: X | F8: Thread 5 | G8: Know Before You Go | H8: Visa in 60 | I8: Evergreen visa | J8: Schengen 5-year visa thread | K8: فيزا شنغن ٥ سنوات للسعوديين: الدليل المختصر 🧵 | N8: ١/ فيزا شنغن متعددة لين ٥ سنوات للسعوديين المقيمين بالمملكة، حتى في أول طلب. الدليل المختصر 🧵 ٢/ المدة تقررها السفارة حسب ملفك. السفر السابق والملف المرتب يفرقون. ٣/ قدّم قبل سفرك بـ٣ إلى ٦ أسابيع، ولا تقدم قبل أكثر من ٦ شهور. ٤/ الأساسيات: جواز ساري، كشف حساب، خطاب جهة العمل، تأمين سفر، حجوزات. ٥/ تبي نجهز ملفك ونحجز موعدك؟ نسويها لك من البداية للنهاية. | O8: 1/ Saudis living in KSA can get a multiple-entry Schengen visa of up to 5 years, even on a first application. 2/ The embassy decides the validity. 3/ Apply 3-6 weeks before travel, never more than 6 months. 4/ Basics: passport, bank statement, employer letter, insurance, bookings. 5/ Want us to prepare your file? | P8: تأشيرة شنغن, Schengen visa | Q8: #تأشيرة_شنغن | R8: DM / WhatsApp | S8: Text-only thread (text posts carry the highest median engagement on X per Buffer 2026). One image on tweet 1: a branded checklist card. | T8: Space threads at least 3 hours from other posts. X downranks bursts from the same author. | V8: Scripted | AC8: =IF(OR(W8="",W8=0),"",(Y8+Z8+AA8+AB8)/W8)
A9: 8 | B9: 46329 | C9: Tue | D9: 20:30 | E9: Instagram | F9: Static 4:5 | G9: Moments & Offers | I9: Launch week | J9: A note from our founder | K9: In Arabia, no guest walks alone. | L9: “In Arabia, no guest walks alone.” Bader Al Sulaiman | M9: «في جزيرة العرب، ما يمشي ضيف وحده.» بدر السليمان | N9: في جزيرة العرب، ما يمشي ضيف وحده. هذا الوعد اللي بنينا عليه مادا: كل مسافر، كل فريق، وكل فكرة تجي للمملكة… معها أحد. — بدر السليمان، المؤسس والرئيس التنفيذي | O9: In Arabia, no guest walks alone. That promise is what Mada is built on: every traveller, every team and every idea that comes to the Kingdom has someone with them. Bader Al Sulaiman, Founder & CEO. | P9: مادا, بدر السليمان | Q9: #مادا #MadaTrips #ضيافة #الرياض | R9: Follow for the journey | S9: Founder portrait (assets/img/founder.jpg) in green duotone, quote in Instrument Serif italic EN + Aref Ruqaa AR, signature at bottom. | T9: APPROVAL: the quote is still draft copy (see README). Get Bader's sign-off before scheduling. | V9: Scripted | AC9: =IF(OR(W9="",W9=0),"",(Y9+Z9+AA9+AB9)/W9)
A10: 9 | B10: 46329 | C10: Tue | D10: 21:00 | E10: TikTok | F10: Video 45s | G10: Horizons | I10: Riyadh Season 2026 (from 21 Oct) | J10: 5 things nobody tells you about Riyadh Season | K10: On-screen: ٥ أشياء محد يقولها لك عن موسم الرياض 🤫 | L10: 5 things nobody tells you about Riyadh Season | M10: ٥ أشياء محد يقولها لك عن موسم الرياض | N10: موسم الرياض ٢٠٢٦ بدأ ✨ بس قبل تروح… هذي ٥ أشياء محد يقولها لك 👇 أي وحدة كنت تعرفها؟ | O10: Riyadh Season 2026 is on. Before you go, here are 5 things nobody tells you. Which one did you already know? | P10: موسم الرياض, موسم الرياض ٢٠٢٦, Riyadh Season 2026, بوليفارد وورلد | Q10: #موسم_الرياض #بوليفارد_وورلد #الرياض #RiyadhSeason #مادا | R10: Comment which tip you didn't know | S10: Fast list format, one tip per 7-8s, real footage from Boulevard World and Boulevard City: (1) book tickets ahead on the official app (2) weekdays after 9pm are calmer (3) comfortable shoes, it's a lot of walking (4) agree a meeting point, signal drops in crowds (5) check each zone's opening days. Text + VO. | T10: Verify zone hours on the official channels the morning of posting. | V10: Scripted | AC10: =IF(OR(W10="",W10=0),"",(Y10+Z10+AA10+AB10)/W10)
A11: 10 | B11: 46329 | C11: Tue | D11: 12:00 | E11: X | F11: Post | G11: One Call | I11: Airline schedule changes after the October RUH closures | J11: Disruption help line | K11: رحلتك تأثرت بتعديلات الطيران الأخيرة؟ | N11: رحلتك تأثرت بتعديلات الطيران الأخيرة؟ أرسل لنا رقم الحجز على الواتساب، ونتابع لك خيارات التعديل أو الاسترداد مع شركة الطيران، بدون ما تنتظر على الخط. حتى لو ما حجزت معنا. | O11: Was your flight affected by recent schedule changes? Send us your booking reference on WhatsApp and we'll chase change or refund options with the airline. Even if you didn't book with us. | P11: تعديل رحلة, استرداد تذكرة | R11: WhatsApp | S11: Text only, calm tone. No airport imagery, no mention of attacks. | T11: SENSITIVITY: post only if foreign carriers' suspensions are still affecting travellers that week (check Monday). Never joke about airports or safety. | V11: Scripted | AC11: =IF(OR(W11="",W11=0),"",(Y11+Z11+AA11+AB11)/W11)
A12: 11 | B12: 46329 | C12: Tue | D12: 09:30 | E12: LinkedIn | F12: Document 8 pages | G12: Events & Business | I12: Post-FII10 (26-29 Oct) | J12: Hosting international delegates in Riyadh: the checklist | K12: Page 1: 200 delegates land in Riyadh in 12 weeks. What has to be true? | L12: Hosting delegates in Riyadh: the 2027 checklist | O12: FII10 just wrapped, and 2027's calendar is already filling. If you are hosting international delegates in Riyadh, this is the checklist we run: 1. Visas: business eVisa vs visit visa, lead times per nationality 2. Arrivals: meet-and-assist, fast-track, VIP lanes 3. Rooms: blocks near the venue, release dates, rooming lists 4. Ground: transfer waves timed to sessions, not flights 5. Badging and registration 6. Cultural briefing: dress, prayer times, Friday schedules 7. A single live status board for the host team 8. The after-report: every booking, every riyal Swipe for the full version. Save it for your next event. | P12: delegation management Riyadh, MICE Saudi Arabia, business eVisa Saudi | Q12: #MICE #Riyadh #EventManagement #CorporateTravel | R12: Save + DM 'CHECKLIST' for the editable version | S12: PDF carousel, 1080x1350 pages, sand background, one point per page with a small icon. Documents lead LinkedIn engagement (Buffer 2026, Socialinsider 2026). | V12: Scripted | AC12: =IF(OR(W12="",W12=0),"",(Y12+Z12+AA12+AB12)/W12)
A13: 12 | B13: 46330 | C13: Wed | D13: 20:30 | E13: Instagram | F13: Reel 35s | G13: One Call | H13: One Call | I13: AlUla Skies Festival 6-15 Nov | J13: One Call #1: three rooms for AlUla Skies | K13: Voice note plays: 'نبي ٣ غرف بالعلا ويكند مهرجان السماء…' | L13: One call. 3 rooms. 4 minutes. | M13: مكالمة وحدة. ٣ غرف. ٤ دقائق. | N13: مكالمة وحدة… والويكند جاهز 🎈 سلسلة «مكالمة وحدة»: طلبات حقيقية، وكيف نحلها. وش الطلب اللي تبينا نحله في الحلقة الجاية؟ | O13: One call and the weekend is ready. 'One Call' is our series of real requests and how we solve them. What should we solve next? | P13: مهرجان سماء العلا, فنادق العلا, AlUla Skies Festival | Q13: #مكالمة_وحدة #العلا #سماء_العلا #مادا #AlUla | R13: Comment your request for the next episode | S13: Split screen. Left: the client's voice note waveform + subtitles. Right: the concierge working (calls, screens blurred, confirmations). A running timer top-right. Ends on the client's reply: '😍 تم'. Natural office sound, no music under the voice. | T13: Re-enact with consent and anonymise. Label it 'based on a real request' if re-enacted. | V13: Scripted | AC13: =IF(OR(W13="",W13=0),"",(Y13+Z13+AA13+AB13)/W13)
A14: 13 | B14: 46330 | C14: Wed | D14: 21:00 | E14: TikTok | F14: Video 40s | G14: Horizons | I14: AlUla Skies Festival 6-15 Nov | J14: AlUla Skies Festival: what to do | K14: On-screen + VO: العلا تفتح سماها ٦ نوفمبر 🎈 | L14: AlUla Skies · 6-15 Nov | M14: سماء العلا · ٦–١٥ نوفمبر | N14: مهرجان سماء العلا من ٦ لين ١٥ نوفمبر 🎈🔭 مناطيد الشروق، عروض المناطيد المضيئة بالليل، ورصد النجوم بأظلم ليالي الشهر. مين بتاخذ معك؟ منشنه 👇 | O14: AlUla Skies Festival, 6-15 November: sunrise balloon flights, balloon glow at night and stargazing on the darkest nights of the month. Tag who you're taking. | P14: مهرجان سماء العلا, العلا نوفمبر, منطاد العلا, AlUla Skies | Q14: #العلا #سماء_العلا #منطاد #السعودية #مادا | R14: Tag a friend | S14: Countdown style: 3 beats (balloons at sunrise → balloon glow → stars over the rocks). Use our own AlUla stills/footage. 'Moonless 7-12 Nov' as a pop-up fact. | T14: Confirm the programme (incl. any concert) on Experience AlUla's channels before posting. | V14: Scripted | AC14: =IF(OR(W14="",W14=0),"",(Y14+Z14+AA14+AB14)/W14)
A15: 14 | B15: 46330 | C15: Wed | D15: 18:00 | E15: X | F15: Poll | G15: Horizons | I15: AlUla Skies Festival | J15: AlUla: which one? | K15: في العلا، وش تختار أول؟ | N15: في العلا، وش تختار أول؟ 🏜️ | O15: In AlUla, what do you pick first? | P15: العلا | Q15: #سماء_العلا | R15: Vote | S15: Poll options: 🎈 منطاد الشروق / 🔭 رصد النجوم / 🏛️ جولة الحِجر / 🍽️ عشاء بالصحراء | V15: Scripted | AC15: =IF(OR(W15="",W15=0),"",(Y15+Z15+AA15+AB15)/W15)
A16: 15 | B16: 46331 | C16: Thu | D16: 19:30 | E16: Instagram | F16: Carousel 7 | G16: Horizons | H16: Weekend Radar | I16: Riyadh Season, AlUla Skies, WWE Crown Jewel (7 Nov) | J16: Weekend Radar #1 | K16: Slide 1: This weekend in Riyadh & beyond · 5-7 Nov | L16: Weekend Radar · 5-7 Nov | M16: رادار الويكند · ٥–٧ نوفمبر | N16: رادار الويكند 📡 • موسم الرياض: الأجنحة الجديدة في بوليفارد وورلد (هولندا، البرتغال، اليمن) • العلا: افتتاح مهرجان سماء العلا الجمعة • السبت: ليلة WWE Crown Jewel في الرياض • موسم سباقات الرياض مستمر احفظه وشاركه مع شلتك 📌 | O16: Weekend Radar. Riyadh Season's new Boulevard World pavilions, AlUla Skies opens Friday, WWE Crown Jewel on Saturday, and Riyadh racing season continues. Save and share. | P16: فعاليات الرياض هالويكند, وش اسوي بالرياض, Riyadh this weekend | Q16: #رادار_الويكند #موسم_الرياض #فعاليات_الرياض #الرياض #مادا | R16: Save + share to your group | S16: Recurring template every Thursday: green cover with a radar-sweep graphic, one event per slide with date, place and a one-line tip. Last slide: 'Need tickets, a table or a ride? WhatsApp'. | V16: Scripted | AC16: =IF(OR(W16="",W16=0),"",(Y16+Z16+AA16+AB16)/W16)
A17: 16 | B17: 46331 | C17: Thu | D17: 21:30 | E17: Instagram | F17: Reel 25s | G17: Horizons | I17: AlUla Skies weekend | J17: Pack with me: AlUla in November | K17: Hands open a carry-on: 'AlUla nights are colder than you think' | L17: AlUla in November: pack for two seasons | M17: العلا في نوفمبر: جهز لفصلين | N17: العلا في نوفمبر: النهار دافي والليل بارد 🧥 هذي شنطتنا لثلاث ليالي. وش الشي اللي دايم تنساه؟ | O17: AlUla in November: warm days, cold nights. Here's our bag for 3 nights. What do you always forget? | P17: وش اخذ معي العلا, ملابس العلا, AlUla packing list | Q17: #العلا #شنطة_السفر #سفر #مادا #AlUla | R17: Comment what you always forget | S17: Top-down ASMR packing, no VO. Real sounds (zips, folding). On-screen labels: layers, scarf, walking shoes, power bank, headlamp for stargazing, sunscreen. Last frame: a ready card 'Transfer booked ✓'. | V17: Scripted | AC17: =IF(OR(W17="",W17=0),"",(Y17+Z17+AA17+AB17)/W17)
A18: 17 | B18: 46331 | C18: Thu | D18: 20:00 | E18: TikTok | F18: Video 55s | G18: Horizons | I18: Riyadh Season 2026 | J18: Riyadh Season zones in 60 seconds | K18: VO: موسم الرياض بدقيقة. يلا 🏃 | L18: Riyadh Season in 60s | M18: موسم الرياض بدقيقة | N18: موسم الرياض ٢٠٢٦ بدقيقة ⏱️ وش المنطقة اللي بتبدأ فيها؟ بوليفارد وورلد، بوليفارد سيتي، ونستر غاردن، ذا قروفز، سوق المزارعين، وأنا عربية في ڤيا رياض. | O18: Riyadh Season 2026 in a minute: Boulevard World, Boulevard City, Wonder Garden, The Groves, the Farmers' Market and Ana Arabia at VIA Riyadh. Where do you start? | P18: مناطق موسم الرياض, موسم الرياض ٢٠٢٦, Riyadh Season zones | Q18: #موسم_الرياض #RiyadhSeason #الرياض #فعاليات #مادا | R18: Comment your first zone | S18: Walk-and-talk, one zone per 8s, a location pin pops for each. Keep the zone names on screen for search. | V18: Scripted | AC18: =IF(OR(W18="",W18=0),"",(Y18+Z18+AA18+AB18)/W18)
A19: 18 | B19: 46331 | C19: Thu | D19: 22:00 | E19: TikTok | F19: Photo carousel 6 | G19: Horizons | I19: AlUla Skies | J19: Rate my itinerary: 3 days in AlUla | K19: Slide 1: قيّم برنامجي: ٣ أيام في العلا من ١٠ | L19: Rate my itinerary: AlUla 3 days | M19: قيّم برنامجي: ٣ أيام بالعلا | N19: قيّم برنامجنا من ١٠ 👇 وش تضيف؟ وش تشيل؟ اليوم ١: وصول + غروب عند جبل الفيل اليوم ٢: الحِجر صباحاً + رصد النجوم اليوم ٣: منطاد الشروق + البلدة القديمة | O19: Rate our itinerary out of 10. Day 1: arrival and sunset at Elephant Rock. Day 2: Hegra and stargazing. Day 3: sunrise balloon and the Old Town. | P19: برنامج العلا ٣ ايام, جدول العلا, AlUla itinerary | Q19: #العلا #برنامج_سياحي #سفر #السعودية #مادا | R19: Rate it in comments | S19: TikTok Photo Mode: big readable Arabic text on each slide, one photo per day. Itinerary text on slides is indexed by search. | V19: Scripted | AC19: =IF(OR(W19="",W19=0),"",(Y19+Z19+AA19+AB19)/W19)
A20: 19 | B20: 46331 | C20: Thu | D20: 13:00 | E20: X | F20: Thread 4 | G20: Horizons | H20: Weekend Radar | I20: Weekend | J20: Weekend Radar on X | K20: وش نسوي هالويكند؟ 📡 | N20: وش نسوي هالويكند؟ 📡 رادار مادا: ١/ موسم الرياض: أجنحة جديدة ببوليفارد وورلد (هولندا، البرتغال، اليمن) ٢/ العلا: مهرجان سماء العلا يبدأ الجمعة ٦ نوفمبر ٣/ السبت ٧ نوفمبر: WWE Crown Jewel تبي تذاكر أو حجز أو توصيل؟ كلمنا. | O20: What's on this weekend: Riyadh Season's new pavilions, AlUla Skies opens Friday, WWE Crown Jewel on Saturday. Need tickets, a booking or a ride? Talk to us. | P20: فعاليات الويكند | Q20: #موسم_الرياض | R20: Reply / DM | S20: Image on tweet 1 = cover slide of the IG Weekend Radar. | V20: Scripted | AC20: =IF(OR(W20="",W20=0),"",(Y20+Z20+AA20+AB20)/W20)
A21: 20 | B21: 46332 | C21: Fri | D21: 20:30 | E21: Instagram | F21: Reel 20s | G21: Horizons | I21: AlUla Skies opening day | J21: 06:00 in AlUla (balloon ASMR) | K21: Sound of the burner first, then black → sunrise | L21: 06:00 · AlUla | M21: ٦ الفجر · العلا | N21: ٦ الفجر في العلا 🎈 بدون كلام. ارفع الصوت. | O21: 6 a.m. in AlUla. No words. Sound on. | P21: منطاد العلا, AlUla hot air balloon, سماء العلا | Q21: #العلا #سماء_العلا #منطاد #AlUla #مادا | R21: Share to someone who'd love this | S21: Pure ASMR: burner roar, wind, quiet gasps. Wide sunrise over the sandstone, then a detail of hands on the basket. No music. No text except the time stamp. | T21: Needs our own crew/creator in AlUla 6-8 Nov. Fallback: swap with the 'One Call #1' cut-down. Do not repost festival footage. | V21: Scripted | AC21: =IF(OR(W21="",W21=0),"",(Y21+Z21+AA21+AB21)/W21)
A22: 21 | B22: 46332 | C22: Fri | D22: 21:00 | E22: TikTok | F22: Video 15s | G22: Horizons | I22: AlUla Skies | J22: POV: 6am in AlUla | K22: On-screen: POV: صحيت ٥ الفجر عشان هذا 👇 | L22: POV: woke up at 5am for this | M22: POV: صحيت ٥ الفجر عشان هذا | N22: يستاهل ولا لا؟ 🎈 #سماء_العلا | O22: Worth it or not? | P22: منطاد العلا, POV العلا | Q22: #سماء_العلا #العلا #POV #السعودية #مادا | R22: Comment 'worth it' or 'no' | S22: Sleepy alarm at 05:00 (relatable) → cut to balloon lift-off on the beat. Short loopable edit. | V22: Scripted | AC22: =IF(OR(W22="",W22=0),"",(Y22+Z22+AA22+AB22)/W22)
A23: 22 | B23: 46332 | C23: Fri | D23: 18:30 | E23: X | F23: Post + image | G23: Horizons | I23: AlUla Skies | J23: AlUla Skies opens today | K23: اليوم يبدأ مهرجان سماء العلا 🎈 | N23: اليوم يبدأ مهرجان سماء العلا 🎈 نصيحة من فريقنا: أظلم الليالي من ٧ لين ١٢ نوفمبر. إذا جيت عشان النجوم، هذي ليالينا. | O23: AlUla Skies Festival starts today. Tip from our team: the darkest nights are 7-12 November. If you're coming for the stars, these are the nights. | P23: سماء العلا | Q23: #سماء_العلا | R23: Bookmark | S23: One original night-sky photo. | T23: Post after Maghrib. Avoid the Friday prayer window. | V23: Scripted | AC23: =IF(OR(W23="",W23=0),"",(Y23+Z23+AA23+AB23)/W23)
A24: 23 | B24: 46333 | C24: Sat | D24: 20:00 | E24: Instagram | F24: Carousel 6 | G24: Know Before You Go | I24: WWE Crown Jewel (7 Nov) | J24: Big night in Riyadh: the stress-free plan | K24: Slide 1: Event night in Riyadh? Here's the plan that never fails | L24: Event night in Riyadh: the no-stress plan | M24: ليلة فعالية بالرياض؟ الخطة اللي ما تخذلك | N24: عندك فعالية الليلة؟ 🎟️ الخطة اللي نعطيها عملاءنا: وصول بدري، نقطة التقاء واضحة، عشاء محجوز قبل، وتوصيل جاهز بعد. احفظها لأي ليلة كبيرة. | O24: Got an event tonight? The plan we give our clients: arrive early, agree a meeting point, book dinner before, have your ride ready after. Save it for any big night. | P24: فعاليات الرياض, Crown Jewel Riyadh, حفلات الرياض | Q24: #فعاليات_الرياض #موسم_الرياض #الرياض #مادا #RiyadhSeason | R24: Save | S24: Checklist design, 5 slides with icons + 1 CTA slide. Timeline graphic 18:00 → 00:30. | V24: Scripted | AC24: =IF(OR(W24="",W24=0),"",(Y24+Z24+AA24+AB24)/W24)
A25: 24 | B25: 46333 | C25: Sat | D25: 21:30 | E25: TikTok | F25: Video 20s | G25: Moments & Offers | I25: WWE Crown Jewel night | J25: Riyadh tonight | K25: On-screen: الرياض الليلة 🔥 | L25: Riyadh tonight | M25: الرياض الليلة | N25: الرياض الليلة غير 🔥 وين كنتم؟ | O25: Riyadh tonight hits different. Where were you? | P25: الرياض الليلة, موسم الرياض | Q25: #الرياض #موسم_الرياض #CrownJewel #RiyadhSeason #مادا | R25: Comment where you were | S25: Atmosphere-only edit: crowds, lights, food stalls, the boulevard skyline. No match or arena footage (rights). Trending sound. | T25: No WWE logos or broadcast footage. | V25: Scripted | AC25: =IF(OR(W25="",W25=0),"",(Y25+Z25+AA25+AB25)/W25)
A26: 25 | B26: 46333 | C26: Sat | D26: 19:00 | E26: X | F26: Post | G26: Moments & Offers | I26: WWE Crown Jewel | J26: Crown Jewel night tip | K26: رايح #CrownJewel الليلة؟ | N26: رايح #CrownJewel الليلة؟ 🎟️ ثلاث نصايح: ١) وصل قبل البداية بساعة ٢) اتفق مع ربعك على نقطة التقاء ٣) حدد مكان الركوب للرجعة من الحين. استمتعوا! | O26: Going to Crown Jewel tonight? Arrive an hour early, agree a meeting point, pick your ride-home spot now. Enjoy! | P26: Crown Jewel الرياض | Q26: #CrownJewel | R26: Reply | S26: Text only. | V26: Scripted | AC26: =IF(OR(W26="",W26=0),"",(Y26+Z26+AA26+AB26)/W26)
A27: 26 | B27: 46334 | C27: Sun | D27: 20:30 | E27: Instagram | F27: Reel 40s | G27: One Call | H27: Concierge Confessions | I27: Evergreen | J27: Concierge Confessions #1: the 3am call | K27: Phone lights up at 03:12. 'Hello… Mada?' | L27: 03:12 · a call we'll never forget | M27: ٣:١٢ الفجر · مكالمة ما ننساها | N27: الساعة ٣:١٢ الفجر… واحد من عملاءنا في مطار بعيد، والرحلة ألغيت. هذي القصة كاملة 👇 «من دفتر الكونسيرج»: قصص حقيقية من شغلنا اليومي. | O27: 03:12. A client at a faraway airport, flight cancelled. Here's the whole story. 'Concierge Confessions': real stories from our day-to-day. | P27: كونسيرج سفر, إلغاء رحلة, travel concierge | Q27: #من_دفتر_الكونسيرج #مادا #سفر #MadaTrips #قصص_سفر | R27: Save + follow the series | S27: Storytime, concierge to camera in a dim office, cutaways to a phone screen and a departure board. Calm, human, slightly funny ending. 40s max. | T27: Real story, anonymised, with the client's OK. | V27: Scripted | AC27: =IF(OR(W27="",W27=0),"",(Y27+Z27+AA27+AB27)/W27)
A28: 27 | B28: 46334 | C28: Sun | D28: 21:00 | E28: TikTok | F28: Video 50s | G28: Know Before You Go | H28: Visa in 60 | I28: Winter in London (Winter Wonderland from 19 Nov) | J28: UK ETA for Saudis | K28: On-screen + VO: بريطانيا بدون فيزا؟ إيه، بس لازم هذا 👇 | L28: UK: no visa, but you need an ETA | M28: بريطانيا بدون فيزا… بس لازم ETA | N28: السعوديين يدخلون بريطانيا بالـETA بدل الفيزا 🇬🇧 كيف تطلعها، كم صلاحيتها، ووش الغلط اللي يأخر الموافقة 👇 | O28: Saudis enter the UK with an ETA instead of a visa. How to get it, how long it lasts and the mistake that delays approval. | P28: تأشيرة بريطانيا, ETA بريطانيا للسعوديين, UK ETA Saudi | Q28: #بريطانيا #تأشيرة #لندن #سفر #مادا | R28: Save + send to your London crew | S28: Phone screen-record of the official UK ETA app (no personal data), concierge voice-over. Facts on screen: apply via the official app or gov.uk, multiple entries, valid 2 years or until the passport expires, stays up to 6 months. Fee: show the current gov.uk figure. | T28: Verify the fee on gov.uk/eta the day before. Third-party sources say £20 from Feb 2026. | V28: Scripted | AC28: =IF(OR(W28="",W28=0),"",(Y28+Z28+AA28+AB28)/W28)
A29: 28 | B29: 46334 | C29: Sun | D29: 12:30 | E29: X | F29: Thread 4 | G29: Know Before You Go | H29: Visa in 60 | I29: Evergreen visa | J29: UK ETA thread | K29: مسافر لندن هالشتاء؟ لا تنسى الـETA 🇬🇧🧵 | N29: ١/ مسافر لندن هالشتاء؟ السعوديين يحتاجون ETA مو فيزا 🧵 ٢/ تطلعها من التطبيق الرسمي أو gov.uk، والموافقة عادة سريعة. ٣/ صالحة سنتين أو لين ينتهي الجواز، دخول متعدد، لين ٦ شهور لكل زيارة. ٤/ تأكد إن رقم الجواز نفسه اللي بتسافر فيه، هذا أكثر غلط نشوفه. | O29: 1/ Flying to London this winter? Saudis need an ETA, not a visa. 2/ Apply in the official app or on gov.uk. 3/ Valid 2 years or until the passport expires, multiple entries, up to 6 months per visit. 4/ Make sure it's the passport you'll travel on. That's the most common mistake we see. | P29: ETA بريطانيا | Q29: #بريطانيا | R29: Bookmark | S29: Text thread. | T29: Verify on gov.uk. | V29: Scripted | AC29: =IF(OR(W29="",W29=0),"",(Y29+Z29+AA29+AB29)/W29)
A30: 29 | B30: 46334 | C30: Sun | D30: 09:30 | E30: LinkedIn | F30: Document 10 pages | G30: Events & Business | H30: Field Notes | I30: Evergreen B2B | J30: Field Notes #1: a 200-person delegation, the 12-week timeline | K30: Page 1: Week -12 to Day 0 | L30: 200 delegates. 12 weeks. One plan. | O30: Field Notes #1. What it takes to bring 200 people to Riyadh for a three-day summit. Week -12: brief, budget, dates, room block Week -10: visa matrix by nationality Week -8: flights in waves, transfer plan Week -6: run of show v1, suppliers locked Week -4: rooming list, badges, dietary needs Week -2: rehearsal, transport dry-run Day 0: arrivals desk live, status board open The keynote gets the applause. The timeline gets everyone into the room. What would you add? | P30: delegation management, conference planning Saudi Arabia, MICE Riyadh | Q30: #FieldNotes #MICE #EventPlanning #Riyadh | R30: Comment what you'd add | S30: PDF document, a Gantt-style timeline across pages in brand green and gold. | V30: Scripted | AC30: =IF(OR(W30="",W30=0),"",(Y30+Z30+AA30+AB30)/W30)
A31: 30 | B31: 46335 | C31: Mon | D31: 20:30 | E31: Instagram | F31: Carousel 8 | G31: Horizons | I31: New moon 9 Nov · AlUla Skies | J31: The darkest nights of the year are this week | K31: Slide 1: The darkest sky of November is this week. Here's where to see it. | L31: Darkest skies: 7-12 Nov | M31: أظلم ليالي نوفمبر: ٧–١٢ | N31: هالأسبوع بدون قمر 🌑 يعني أوضح نجوم بالسنة تقريباً. وين تشوفها: العلا، صحراء الرياض بعيد عن الأنوار، وحافة العالم. ونصيحة: الأحد ١٥ نوفمبر ذروة شهب الأسد 🌠 | O31: No moon this week means some of the clearest stars of the year. Where to see them: AlUla, the desert outside Riyadh away from city lights, Edge of the World. And on Sunday 15 Nov the Leonid meteor shower peaks. | P31: رصد النجوم, نجوم العلا, شهب الاسد, stargazing Saudi | Q31: #رصد_النجوم #العلا #شهب_الأسد #السعودية #مادا | R31: Save | S31: Night photography slides, a moon-phase strip graphic on slide 2, map of 3 spots, tips (red light, 20 min for eyes to adjust, warm layers). | V31: Scripted | AC31: =IF(OR(W31="",W31=0),"",(Y31+Z31+AA31+AB31)/W31)
A32: 31 | B32: 46335 | C32: Mon | D32: 21:00 | E32: TikTok | F32: Video 30s | G32: Horizons | I32: New moon 9 Nov | J32: Why tonight is the darkest night | K32: VO: الليلة ما فيه قمر… وهذا خبر حلو 🌑 | L32: No moon tonight. Good news. | M32: الليلة بدون قمر… وهذا خبر حلو | N32: ليش الليالي اللي بدون قمر أحلى للنجوم؟ 🌑✨ وين تشوفها قريب منك؟ | O32: Why moonless nights are best for stars, and where to see them near you. | P32: رصد النجوم الرياض, وين اشوف النجوم | Q32: #رصد_النجوم #الرياض #العلا #السعودية #مادا | R32: Comment your city | S32: Explainer with a simple animation of moon phases, then real stars timelapse. | V32: Scripted | AC32: =IF(OR(W32="",W32=0),"",(Y32+Z32+AA32+AB32)/W32)
A33: 32 | B33: 46335 | C33: Mon | D33: 21:30 | E33: X | F33: Post | G33: Horizons | I33: New moon | J33: Stargazing nudge | K33: الليلة بدون قمر 🌑 | N33: الليلة بدون قمر 🌑 لو تقدر تطلع ساعة برا الرياض بعيد عن الأنوار، ارفع راسك. وصورنا اللي تشوفه وحطه بالرد ✨ | O33: No moon tonight. If you can get an hour outside Riyadh away from the lights, look up. Reply with what you see. | P33: رصد النجوم | Q33: #رصد_النجوم | R33: Reply with a photo (UGC) | S33: Text + one star photo. | V33: Scripted | AC33: =IF(OR(W33="",W33=0),"",(Y33+Z33+AA33+AB33)/W33)
A34: 33 | B34: 46336 | C34: Tue | D34: 20:30 | E34: Instagram | F34: Reel 30s | G34: Events & Business | H34: Behind the Curtain | I34: Evergreen events | J34: Behind the Curtain #1: an event build in 30 seconds | K34: Empty hall → full stage in 3 seconds (timelapse hook) | L34: 36 hours in 30 seconds | M34: ٣٦ ساعة في ٣٠ ثانية | N34: قاعة فاضية… وبعد ٣٦ ساعة صارت ليلة ما تنسى ✨ «خلف الستارة»: كيف تنبني فعالياتنا. | O34: An empty hall, and 36 hours later a night nobody forgets. 'Behind the Curtain': how our events get built. | P34: تنظيم فعاليات الرياض, event management Riyadh, تنظيم حفلات | Q34: #خلف_الستارة #تنظيم_فعاليات #فعاليات_الرياض #مادا #MadaEvents | R34: DM 'EVENT' to plan yours | S34: Locked-off timelapse of a real build (stage, truss, lights, tables), then a 3-second real-time payoff of lights on. Crew in branded tees. A sound design build-up. | T34: Needs our own event footage. If no build this month, shoot a small activation or rehearsal. | V34: Scripted | AC34: =IF(OR(W34="",W34=0),"",(Y34+Z34+AA34+AB34)/W34)
A35: 34 | B35: 46336 | C35: Tue | D35: 21:00 | E35: TikTok | F35: Photo carousel 7 | G35: Horizons | I35: AlUla Skies | J35: What a weekend in AlUla actually costs | K35: Slide 1: كم تكلف ويكند بالعلا فعلياً؟ 💸 | L35: AlUla weekend: the real cost | M35: ويكند العلا: التكلفة الحقيقية | N35: كم تكلف ويكند بالعلا فعلياً؟ فصلناها لك بند بند 👇 الأسعار تقريبية لشخصين، وتتغير حسب الموسم. | O35: What does a weekend in AlUla actually cost? Line by line, for two people, approximate and seasonal. | P35: كم تكلف رحلة العلا, اسعار العلا, AlUla trip cost | Q35: #العلا #ميزانية_السفر #سفر #السعودية #مادا | R35: Comment 'تفاصيل' and we'll DM the plan | S35: Photo Mode, one cost line per slide: flights, stay (2 nights), transfers, Hegra, balloon, dinner. Total on the last slide. Clean and transparent, no luxury flexing. | T35: SALES must fill in real SAR ranges before posting. Keep the tone as transparency, not luxury flexing (GAMR rules, Sep 2025). | V35: Scripted | AC35: =IF(OR(W35="",W35=0),"",(Y35+Z35+AA35+AB35)/W35)
A36: 35 | B36: 46336 | C36: Tue | D36: 13:00 | E36: X | F36: Post | G36: Moments & Offers | I36: 11.11 Singles Day | J36: 11.11 teaser | K36: بكرة ١١.١١ 👀 | N36: بكرة ١١.١١ 👀 عندنا شي صغير لأول ١١ حجز. فعّل التنبيه. | O36: Tomorrow is 11.11. Something small for the first 11 bookings. Turn on notifications. | P36: عروض ١١.١١ | Q36: #١١_١١ | R36: Turn on notifications | S36: Text only. | T36: OFFER needs management approval (see 11 Nov). | V36: Scripted | AC36: =IF(OR(W36="",W36=0),"",(Y36+Z36+AA36+AB36)/W36)
A37: 36 | B37: 46336 | C37: Tue | D37: 09:30 | E37: LinkedIn | F37: Post + image | G37: Events & Business | I37: Evergreen B2B | J37: Hiring skilled crews in KSA: what actually takes time | K37: The welders were ready in 10 days. The paperwork took the rest. | L37: Mobilising skilled crews in KSA: where time goes | O37: Clients often ask why mobilising a skilled crew takes weeks when the people are ready in days. Where the time goes: • Work visas and permits through Qiwa • Medical checks and certification checks • Iqama issuance and site access • Housing, transport and safety induction What shortens it: a clear scope early, documents checked before submission, and one partner who owns every step. Timelines vary by role and nationality. If you are planning a 2027 mobilisation, start the conversation now. | P37: manpower supply Saudi Arabia, skilled workers KSA, Qiwa work visa | Q37: #Manpower #SaudiArabia #Workforce #Qiwa | R37: Message us | S37: One image: an infographic bar showing days per stage (illustrative, labelled as such). | T37: Ops to confirm the process steps match our actual workflow. | V37: Scripted | AC37: =IF(OR(W37="",W37=0),"",(Y37+Z37+AA37+AB37)/W37)
A38: 37 | B38: 46337 | C38: Wed | D38: 20:30 | E38: Instagram | F38: Static 4:5 | G38: Moments & Offers | I38: 11.11 Singles Day / ~1 Jumada II | J38: 11.11: 11 bookings, 11 upgrades | K38: 11.11 · 11 bookings · 11 upgrades | L38: 11.11 · The first 11 bookings get an upgrade on us | M38: ١١.١١ · أول ١١ حجز… الترقية علينا | N38: ١١.١١ ✨ أول ١١ حجز اليوم: ترقية علينا (غرفة أعلى، توصيل خاص، أو تشيك آوت متأخر). بدون أكواد. بس قل «١١» على الواتساب. | O38: 11.11. The first 11 bookings today get an upgrade on us: a better room, a private transfer or late checkout. No codes. Just say '11' on WhatsApp. | P38: عروض ١١.١١, عروض سفر | Q38: #عروض_سفر #١١_١١ #مادا #MadaTrips #الرياض | R38: WhatsApp '11' | S38: Typographic poster: huge '11.11' in gold on green, a short line, symbol. Story version with a countdown sticker. | T38: OFFER: management approval + terms (valid today only, subject to availability). | V38: Scripted | AC38: =IF(OR(W38="",W38=0),"",(Y38+Z38+AA38+AB38)/W38)
A39: 38 | B39: 46337 | C39: Wed | D39: 21:00 | E39: TikTok | F39: Video 20s | G39: Moments & Offers | I39: 11.11 | J39: 11.11: what an 'upgrade' means | K39: On-screen: وش يعني «ترقية» عندنا؟ 👇 | L39: What 'upgrade' means at Mada | M39: وش يعني «ترقية» عندنا | N39: اليوم بس: أول ١١ حجز ياخذون ترقية ✨ قل «١١» على الواتساب. | O39: Today only: the first 11 bookings get an upgrade. Say '11' on WhatsApp. | P39: عروض ١١.١١ | Q39: #١١_١١ #عروض_سفر #سفر #السعودية #مادا | R39: WhatsApp '11' | S39: Three quick reveals: the room view, the private car door, the 'late checkout' sign. Fun, fast. | T39: OFFER approval. | V39: Scripted | AC39: =IF(OR(W39="",W39=0),"",(Y39+Z39+AA39+AB39)/W39)
A40: 39 | B40: 46337 | C40: Wed | D40: 12:00 | E40: X | F40: Post | G40: Moments & Offers | I40: 11.11 | J40: 11.11 live | K40: ١١.١١ بدأ ✨ | N40: ١١.١١ بدأ ✨ أول ١١ حجز اليوم ياخذون ترقية علينا. قل «١١» على الواتساب ‎+966 56 668 2662 | O40: 11.11 is live. The first 11 bookings today get an upgrade. Say '11' on WhatsApp. | P40: عروض ١١.١١ | Q40: #١١_١١ | R40: WhatsApp | S40: Poster image. | T40: Post 'all 11 gone' update once claimed (scarcity proof). | V40: Scripted | AC40: =IF(OR(W40="",W40=0),"",(Y40+Z40+AA40+AB40)/W40)
...

Sheet Month view
A1: November 2026 at a glance
A2: Saudi week: Sunday-Thursday work, Friday-Saturday weekend. Bold = moment of the day.
A4: Sunday | B4: Monday | C4: Tuesday | D4: Wednesday | E4: Thursday | F4: Friday | G4: Saturday
A5: 1 Nov — Brand launch IN · Reel · Launch film: Every horizon, within reach TI · Video · POV: you said it once and it just happened X · Post · Launch post LI · Image · Mada Trips opens its doors | B5: 2 Nov — Launch week IN · Carousel · 9 services. 1 call. TI · Video · Schengen 5-year visa for Saudis X · Thread · Schengen 5-year visa thread | C5: 3 Nov — Launch week IN · Static · A note from our founder TI · Video · 5 things nobody tells you about Riyadh Season X · Post · Disruption help line LI · Document · Hosting international delegates in Riyadh: the checklist | D5: 4 Nov — AlUla Skies Festival 6-15 Nov IN · Reel · One Call #1: three rooms for AlUla Skies TI · Video · AlUla Skies Festival: what to do X · Poll · AlUla: which one? | E5: 5 Nov — Riyadh Season, AlUla Skies, WWE Crown Jewel (7 Nov) IN · Carousel · Weekend Radar #1 IN · Reel · Pack with me: AlUla in November TI · Video · Riyadh Season zones in 60 seconds TI · Photo · Rate my itinerary: 3 days in AlUla X · Thread · Weekend Radar on X | F5: 6 Nov — AlUla Skies opening day IN · Reel · 06:00 in AlUla (balloon ASMR) TI · Video · POV: 6am in AlUla X · Post · AlUla Skies opens today | G5: 7 Nov — WWE Crown Jewel (7 Nov) IN · Carousel · Big night in Riyadh: the stress-free plan TI · Video · Riyadh tonight X · Post · Crown Jewel night tip
A6: 8 Nov — Winter in London (Winter Wonderland from 19 Nov) IN · Reel · Concierge Confessions #1: the 3am call TI · Video · UK ETA for Saudis X · Thread · UK ETA thread LI · Document · Field Notes #1: a 200-person delegation, the 12-week timeline | B6: 9 Nov — New moon 9 Nov · AlUla Skies IN · Carousel · The darkest nights of the year are this week TI · Video · Why tonight is the darkest night X · Post · Stargazing nudge | C6: 10 Nov — AlUla Skies IN · Reel · Behind the Curtain #1: an event build in 30 seconds TI · Photo · What a weekend in AlUla actually costs X · Post · 11.11 teaser LI · Post · Hiring skilled crews in KSA: what actually takes time | D6: 11 Nov — 11.11 Singles Day / ~1 Jumada II IN · Static · 11.11: 11 bookings, 11 upgrades TI · Video · 11.11: what an 'upgrade' means X · Post · 11.11 live | E6: 12 Nov — Vienna Schönbrunn market from 6 Nov · Rathausplatz ~13 Nov IN · Carousel · Weekend Radar #2 IN · Reel · Vienna in winter: 3 days TI · Video · Europe this winter: 5 cities ranked for families TI · Video · Reply: how long does a Schengen visa take? X · Thread · Europe's winter markets 2026: opening dates LI · Post · Why we answer at 3 a.m. | F6: 13 Nov — World Kindness Day (13 Nov) IN · Reel · Small things we do that nobody asks for TI · Video · Things we do without being asked X · Post · World Kindness Day question | G6: 14 Nov — School autumn break 20-28 Nov IN · Carousel · Autumn break: 6 short trips from Riyadh TI · Video · Autumn break in 6 days: 5 nearby escapes X · Post · Autumn break countdown
A7: 15 Nov — Leonids peak 15 Nov · AlUla Skies closes IN · Reel · Tonight: the Leonids TI · Video · Where to see the meteors near Riyadh X · Post · Leonids alert LI · Document · Cityscape Global week: visitor logistics | B7: 16 Nov — International Day for Tolerance (16 Nov) · Cityscape visitors IN · Carousel · Hosting guests from abroad: a Saudi hospitality guide TI · Video · Saudi coffee etiquette in 30 seconds X · Thread · Cityscape Global: visitor tips | C7: 17 Nov — Autumn break IN · Reel · One Call #2: a family of 7, 48 hours to plan TI · Photo · Autumn-break packing list for kids X · Poll · Autumn break: where? LI · Document · Field Notes #2: why delegates remember logistics, not keynotes | D7: 18 Nov — Lufthansa's planned return (18 Nov) IN · Static · Schengen document checklist (save-worthy) TI · Video · US visa: book your interview early X · Post · Routes update (conditional) | E7: 19 Nov — School break starts 20 Nov IN · Carousel · Weekend Radar #3: break edition IN · Reel · London in winter: ETA + Winter Wonderland + 4 more TI · Video · Last workday before the break TI · Photo · Airport-day checklist X · Post · Last-minute break trips LI · Image · Horizon Keepers #1: meet our visa desk | F7: 20 Nov — Autumn break starts 20 Nov IN · Reel · Break mode: ON TI · Video · Muscat in 48 hours X · Post · Safe travels + 24/7 line | G7: 21 Nov — Desert camping season · break weekend IN · Carousel · Kashta season: the desert camp checklist TI · Video · Kashta setup ASMR X · Poll · Kashta must-have
A8: 22 Nov — Break week · Riyadh Season IN · Reel · Concierge Confessions #2: the 2am rebooking TI · Video · Riyadh Season with family: the 1-day plan X · Thread · Riyadh Season with family thread LI · Document · Field Notes #3: 5 travel-policy clauses that save money in 2027 | B8: 23 Nov — Trend: destination dupes IN · Carousel · Destination dupes: love X? try Y TI · Video · Dupes: Switzerland? Try this X · Thread · Visa-free reminders: China & Russia | C8: 24 Nov — Trend: day in the life / Reali-TEA IN · Reel · Behind the Curtain #2: a gala run to the second TI · Video · Day in the life of a Mada concierge X · Post · White Friday teaser LI · Image · Specialist supply: the expert you couldn't find | D8: 25 Nov — White Friday countdown IN · Static · White Friday: 2 days TI · Video · Travel myths: real or fake? X · Thread · Booking myths thread | E8: 26 Nov — F1 Qatar 27-29 Nov · White Friday IN · Carousel · Weekend Radar #4 IN · Reel · White Friday tomorrow: how it works TI · Video · F1 Qatar weekend: Riyadh to Doha TI · Video · White Friday preview X · Post · White Friday rules LI · Post · Plan Q1 2027 events at 2026 rates | F8: 27 Nov — White Friday 27 Nov IN · Carousel · White Friday: the offer IN · Reel · White Friday: final hours TI · LIVE · White Friday LIVE: Ask the concierge X · Post · White Friday is live | G8: 28 Nov — End of autumn break IN · Reel · Break recap: where our clients went TI · Video · Last day of the break mood X · Post · How was your trip?
A9: 29 Nov — 1 Rajab 1448 ≈ 10 Dec 2026 IN · Carousel · Rajab starts 10 Dec: plan your Umrah calmly TI · Video · Umrah, step by step #1: before you go X · Post · Ramadan Umrah: book early LI · Post · Our first month, in numbers | B9: 30 Nov — December preview IN · Reel · December on the horizon TI · Video · December in Saudi & the Gulf: 5 dates X · Post · Cyber Monday + December
A11: Shaded gold = school autumn break (20-28 Nov). IG = Instagram · TI = TikTok · X = X · LI = LinkedIn.

Sheet Platform playbook
A1: Platform playbook
A2: Each platform has its own job. Same idea, native execution, never a cross-post.
A4: Platform | B4: Role | C4: Cadence | D4: Language | E4: Best times (AST) | F4: Formats that work | G4: Rules
A5: Instagram | B5: Brand home and conversion. Discovery through Reels, saves and shares through carousels. | C5: 1-2 feed posts a day (35 this month: 18 Reels, 13 carousels, 4 statics) + Stories every day | D5: Arabic first, with English underneath (bilingual captions). On-screen text in Arabic, with English where the post is for visitors. | E5: Weekdays 20:30. Thursday 19:30 (Weekend Radar) + 21:30. Weekend evenings 20:00-21:00. Avoid the Friday prayer window (11:30-13:30). | F5: • Reels 20-45s (up to 3 min allowed): discovery. Instagram ranks on watch time, likes per reach and sends per reach (Mosseri, Jan 2025) • Carousels 6-10 slides, 4:5 or 3:4: the highest engagement per reach (6.9% vs Reels 3.3%, Buffer 2026). Use for itineraries, checklists, radars • Statics: offers, quotes and save-worthy checklists only • Stories daily: polls, question box, BTS, countdowns. Stories don't need to be polished • Trial Reels: test 2 hooks for the same idea on non-followers before posting to the grid | G5: • Max 5 hashtags (cap announced Dec 2025). Use 2-3 topic tags + #مادا • Original footage only. Since 30 Apr 2026 Instagram stops recommending accounts that mostly repost. Work with creators through Collab posts • Grid previews at 3:4, so keep key text in the centre of 4:5 images • Safe zone on Reels: no text in the top ~250px or bottom ~340px • Put the keyword in the first caption line and in the on-screen text
A6: TikTok | B6: Reach and search. The biggest platform in KSA (38.6M ad reach, 154% of adults, highest TikTok penetration in the world). | C6: 1-2 videos a day (34 this month), plus video replies to comments | D6: Saudi Arabic (white Najdi/Khaleeji) in voice and on screen. One English-led video a week for expats and visitors. | E6: 21:00 main slot, 22:00 second slot on Thursdays. 20:00-23:00 is the modelled KSA peak. | F6: • Talking-head explainers 40-60s (Visa in 60). Videos over 60s get 43% more reach (Buffer, 1.1M videos) • Relatable trend videos 15-20s (Reali-TEA, TikTok Next 2026) • Photo Mode carousels for itineraries, costs and checklists. On-slide text is searchable • Reply-to-comment videos: free content ideas and community proof • LIVE once the account has 1,000 followers | G6: • Say the keyword in the first 3 seconds, show it on screen, write it in the caption's first line and use it in 1-2 hashtags. TikTok search reads all four • Max 5 hashtags (cap since mid-2025) • Hook in the first 2 seconds: text overlay + movement. Target a 3-second hold of 35%+ • Burn in captions. Most viewers watch muted • Reply to comments for the first hour after posting
A7: X (Twitter) | B7: News, visa updates, live moments and fast customer care. Where Saudi conversations happen in real time. | C7: 1 planned post a day (30 this month) + 1-3 reactive posts and replies a day | D7: Arabic. Short, direct, dialect-friendly. | E7: 12:00-13:00 for useful posts and threads, 18:00-21:30 for live moments. | F7: • Text posts and threads: the highest median engagement on X (3.56%, Buffer 2026) • Polls for light engagement • Native images (the Weekend Radar cover). Avoid bare links (link posts have the lowest engagement: 2.25%) | G7: • Space posts at least 3 hours apart. X's ranker (open-sourced Jan 2026) downranks the 3rd-5th post from the same author in a short window • Get X Premium (Basic) for the company account. Verified accounts have a higher score ceiling • Reply to every reply in the first hour. Replies feed the ranking • Never argue in public. Move complaints to DM within 15 minutes
A8: LinkedIn | B8: B2B credibility: corporates, delegations, events, manpower, specialists, IT. Lighter touch. | C8: 3 posts a week (12 this month): Sunday, Tuesday, Thursday | D8: English (Arabic for national moments). | E8: 09:30 on Saudi workdays (Sunday-Thursday). | F8: • Document (PDF) carousels: the top LinkedIn format in 2026 (Buffer and Socialinsider) • Founder-voice text posts with one real photo • Team spotlights (Horizon Keepers) | G8: • Teach something in every post (Field Notes). LinkedIn's 2026 ranking cuts low-substance posts and engagement bait • The founder posts and the company page reshares. Personal profiles reach further • Ask the team to comment with substance in the first hour, never just 'congrats' • Put links in the post only when needed. Reach drops with external links (vendor estimates of 25-60%)

Sheet Pillars & series
A1: Content pillars and recurring series
A4: Code | B4: Pillar | C4: Target share | D4: What goes here | E4: Series
A5: ONE | B5: One Call | C5: 20% | D5: The concierge in action: real requests, the 3am rescue, small kind gestures, a day in the life. The human face no competitor shows. | E5: One Call · Concierge Confessions · Horizon Keepers
A6: KNOW | B6: Know Before You Go | C6: 20% | D6: Search-led explainers: visas, checklists, myths, Umrah steps. Built to be saved and found in search. | E6: Visa in 60 · Umrah, Step by Step
A7: HOR | B7: Horizons | C7: 35% | D7: Where to go and how: Riyadh Season, AlUla, short-haul breaks, Europe in winter, dupes, itineraries and real costs. | E7: Weekend Radar · Europe in Winter
A8: BIZ | B8: Events & Business | C8: 10% | D8: Mada Events craft and B2B: delegations, MICE, manpower, specialists, IT. Mostly LinkedIn, plus one events Reel every two weeks. | E8: Behind the Curtain · Field Notes
A9: MOM | B9: Moments & Offers | C9: 15% | D9: The launch, 11.11, World Kindness Day, the break, White Friday, December. Culture and conversion. | E9: Launch · 11.11 · White Friday
A11: Actual mix this month
A12: Code | B12: Pillar | C12: Posts | D12: Share
A13: ONE | B13: One Call | C13: =COUNTIF(Calendar!$G:$G,B13) -> 18 | D13: =IF(SUM($C$13:$C$17)=0,0,C13/SUM($C$13:$C$17)) -> 0.16216216
A14: KNOW | B14: Know Before You Go | C14: =COUNTIF(Calendar!$G:$G,B14) -> 18 | D14: =IF(SUM($C$13:$C$17)=0,0,C14/SUM($C$13:$C$17)) -> 0.16216216
A15: HOR | B15: Horizons | C15: =COUNTIF(Calendar!$G:$G,B15) -> 40 | D15: =IF(SUM($C$13:$C$17)=0,0,C15/SUM($C$13:$C$17)) -> 0.36036036
A16: BIZ | B16: Events & Business | C16: =COUNTIF(Calendar!$G:$G,B16) -> 12 | D16: =IF(SUM($C$13:$C$17)=0,0,C16/SUM($C$13:$C$17)) -> 0.10810811
A17: MOM | B17: Moments & Offers | C17: =COUNTIF(Calendar!$G:$G,B17) -> 23 | D17: =IF(SUM($C$13:$C$17)=0,0,C17/SUM($C$13:$C$17)) -> 0.20720721
A20: Recurring series
A21: Series | B21: Where | C21: How often | D21: Format
A22: One Call / مكالمة وحدة | B22: IG Reel, then TikTok | C22: Every 2 weeks | D22: Split screen: the client's voice note on the left, the concierge solving it on the right, a timer. Ends on the client's reply. The signature format.
A23: Visa in 60 / الفيزا بدقيقة | B23: TikTok, IG, X thread | C23: Weekly | D23: A concierge explains one visa topic in 60 seconds. Keyword spoken in the first 3 seconds. The best search driver.
A24: Weekend Radar / رادار الويكند | B24: IG carousel, X thread | C24: Every Thursday 19:30 | D24: What's on this weekend in Riyadh and nearby, with one tip per event. A habit-forming, save-and-share format.
A25: Concierge Confessions / من دفتر الكونسيرج | B25: IG Reel | C25: Every 2 weeks | D25: Storytime about a real (anonymised) case. Calm, human, a little funny.
A26: Behind the Curtain / خلف الستارة | B26: IG Reel, TikTok | C26: Every 2 weeks | D26: Event builds, show-caller POV, crew. The craft gap among event companies.
A27: Europe in Winter / شتاء أوروبا | B27: IG Reel, TikTok, X | C27: Weekly in Nov-Jan | D27: Winter markets, visas and itineraries for the mid-year break.
A28: Field Notes | B28: LinkedIn document | C28: Weekly | D28: One practical B2B lesson: timelines, checklists, policy clauses.
A29: Horizon Keepers | B29: LinkedIn + IG Story | C29: Monthly | D29: A team member spotlight. The people behind the plan.
A30: Umrah, Step by Step / العمرة خطوة بخطوة | B30: TikTok, IG | C30: Weekly from 29 Nov | D30: Calm, respectful explainers ahead of Rajab and Ramadan. No music, no hard sell.

Sheet Guidelines
A1: Brand voice, design and profile guidelines
A4: Voice & copy | B4: Guideline
A5: We sound like | B5: A calm, capable host who has already thought of it. Warm, short, specific. Saudi dialect on TikTok and X, polished Arabic on IG, clear English on LinkedIn.
A6: We say | B6: 'Say it once. We'll take it from there.' · 'One call. Everything moves.' · 'Every horizon, within reach.' · كل أفق، في متناولك · قلها مرة… والباقي علينا
A7: We never | B7: Flex wealth or price tags (GAMR rules, Sep 2025) · joke about airports, flights or safety · promise visa approvals · use clickbait we can't back up · mock anyone · post children's faces or domestic workers
A8: Hooks that work | B8: A number + a promise ('5 things nobody tells you…') · a POV · a question the viewer has asked themselves ('Schengen for 5 years?') · a sound-first ASMR open · a relatable moment ('Last day before the break')
A9: Captions | B9: Line 1 = the keyword + the hook. 2-4 short lines. One CTA. Emojis as punctuation, max 3. Arabic first, English after a line break on IG.
A10: CTAs (rotate) | B10: Save it · Send it to your travel buddy · Comment your destination · WhatsApp '11' / '🤍' / 'عمرة' · Tag who you're taking
A12: Design | B12: Guideline
A13: Colours | B13: Brand green #1E352D (backgrounds) · Sand #E9E2D8 (light backgrounds) · Gold #D9B77A (accents, numbers, one highlight per post) · Ink #0F1A16. One accent per design.
A14: Type | B14: Latin: Inter Tight (headlines, tight tracking) + Instrument Serif italic (one emphasised word). Arabic: IBM Plex Sans Arabic (body) + Reem Kufi (display words). Aref Ruqaa for signatures and quotes only.
A15: Poster text | B15: Max 7 words in the headline. One idea per slide. Arabic headline larger than English. Min 48px body text at 1080 wide.
A16: Logo | B16: The symbol (sun) bottom-centre or bottom-right on statics, small. Full logo only on cover slides and end cards. Never on Reels' first frame.
... A29: Saturday | B29: Client stories: reshare tagged trips (with permission) + a 'where to next?' sticker.
A31: Profile | B31: Display name | C31: Bio | D31: Note
A32: Instagram | B32: مادا | Mada Trips | C32: سفر · فنادق · تأشيرات · فعاليات من الرياض ✈️ قلها مرة… والباقي علينا Travel · Visas · Events · Riyadh 👇 واتساب | D32: Name field carries keywords: 'مادا للسفر | Mada Trips Riyadh'
A33: TikTok | B33: مادا للسفر | C33: نخطط لك السفر والفيزا والفعاليات 🇸🇦 قلها مرة… والباقي علينا 👇 | D33: Username: @madatrips (secure the same handle everywhere)
A34: X | B34: مادا | Mada Trips | C34: سفر، تذاكر، فنادق، تأشيرات، فعاليات، كوادر وتقنية. من الرياض لكل أفق. واتساب ‎+966 56 668 2662 | D34: Pin the launch post, then the current offer
A35: LinkedIn | B35: Mada Trips | C35: One partner for everything that moves: corporate travel, delegations, events, manpower, specialist supply and IT. Riyadh, KSA. | D35: Tagline + the 9 services under 'Specialties' for search

Sheet Keywords
A1: Keyword bank (search on TikTok, Instagram and Google)
A4: • Search volumes for Arabic terms weren't available. Validate every cluster before posting: TikTok search autocomplete + 'Others searched for', TikTok Creative Center (region: Saudi Arabia) and Google Trends (geo: SA).
A5: • Use one main keyword per post in four places: spoken in the first 3 seconds, on screen, in caption line 1, and in 1-2 of the 5 hashtags.
A6: • Spell it the way people search, which is often colloquial: 'وش اسوي بالرياض', not formal Arabic.
A7: • Put keywords in the profile name field too (e.g. 'مادا للسفر | Mada Trips Riyadh').
A9: Cluster | B9: Arabic keywords | C9: English keywords
A10: Visas | B10: تأشيرة شنغن · فيزا شنغن للسعوديين · شنغن ٥ سنوات · مواعيد السفارة · اوراق الفيزا · ETA بريطانيا · فيزا امريكا · بدون فيزا للسعوديين | C10: Schengen visa Saudi · UK ETA Saudi · US visa Riyadh
A11: Breaks & deals | B11: اجازة الخريف · وين نسافر في الاجازة · رحلات قريبة من الرياض · عروض سفر · عروض طيران · باقات سياحية · الجمعة البيضاء عروض سفر | C11: autumn break Saudi · White Friday travel deals
A12: Domestic | B12: العلا · سماء العلا · منطاد العلا · برنامج العلا ٣ ايام · ابها والسودة · البحر الاحمر · الدرعية · كشتة · مخيمات الرياض · حافة العالم | C12: things to do in AlUla · AlUla Skies · Red Sea resorts · desert camping Riyadh
A13: Riyadh Season | B13: موسم الرياض ٢٠٢٦ · بوليفارد وورلد · فعاليات الرياض هالويكند · وش اسوي بالرياض · موسم الرياض للعائلات | C13: Riyadh Season 2026 · Riyadh this weekend
A14: Abroad | B14: سفر اوروبا شتاء · فيينا في الشتاء · لندن في الشتاء · جورجيا في الشتاء · مسقط سياحة · باكو · تبليسي | C14: Europe winter trip · Vienna Christmas market · Winter Wonderland London
A15: Umrah | B15: باقات عمرة · عمرة رجب · عمرة رمضان · تصريح عمرة نسك · فنادق قريبة من الحرم | C15: Umrah package from Riyadh · Umrah permit Nusuk
